Workbook

Sheet OUT-26
A1: UNIVERSIDADE FEDERAL DO RIO DE JANEIRO — PRÓ-REITORIA DE GESTÃO E GOVERNANÇA (PR-6)
A2: INSTRUMENTO DE MEDIÇÃO DE RESULTADO | H2: IMR Nº | I2: 01
A3: OBJETO | B3: Serviço de manutenção de áreas externas e verdes no Campus Cidade Universitária
A4: EMPRESA | B4: RODOCON CONSTRUÇÕES RODOVIÁRIAS LTDA. | F4: CONTRATO | G4: 04/2023
A5: UNIDADE | B5: PREFEITURA UNIVERSITÁRIA | F5: TERMO | G5: TERMO ADITIVO N° 06/26
A6: MÊS/ANO | B6: 46296 | F6: FISCAL
A7: Preencha as células em amarelo. Pontuação, nota e valores são calculados automaticamente.
A8: AVALIAÇÃO DOS SERVIÇOS
A9: Cód. | B9: Indicador | G9: Avaliação correspondente | H9: Pontos | I9: Peso
A10: Módulo A — QUALIDADE DOS SERVIÇOS | I10: Peso 25
A11: A.1 | B11: CONFORMIDADE DOS EQUIPAMENTOS PARA EXECUÇÃO DOS SERVIÇOS | H11: =IFERROR(VLOOKUP(G11,'Parâmetros'!$A$2:$B$4,2,FALSE),0)
A12: A.2 | B12: CONFORMIDADE DOS SERVIÇOS EXECUTADOS COM AS ESPECIFICAÇÕES TÉCNICAS | H12: =IFERROR(VLOOKUP(G12,'Parâmetros'!$A$2:$B$4,2,FALSE),0)
A13: Pontuação total do Módulo A | H13: =SUM(H11:H12)
A14: Módulo B — EQUIPE DE TRABALHO | I14: Peso 25
A15: B.1 | B15: UNIFORMIZAÇÃO E EQUIPAMENTOS DE PROTEÇÃO INDIVIDUAL | H15: =IFERROR(VLOOKUP(G15,'Parâmetros'!$A$2:$B$4,2,FALSE),0)
A16: B.2 | B16: QUALIDADE DA EQUIPE | H16: =IFERROR(VLOOKUP(G16,'Parâmetros'!$A$2:$B$4,2,FALSE),0)
A17: Pontuação total do Módulo B | H17: =SUM(H15:H16)
A18: Módulo C — CUMPRIMENTO DO CRONOGRAMA | I18: Peso 25
A19: C.1 | B19: CUMPRIMENTO DO CRONOGRAMA E DAS ATIVIDADES | H19: =IFERROR(VLOOKUP(G19,'Parâmetros'!$A$2:$B$4,2,FALSE),0)
A20: Pontuação total do Módulo C | H20: =SUM(H19:H19)
A21: TOTAL DE PONTOS | C21: =(H11+H12+H15+H16+H19)/5 | D21: NOTA OBTIDA | F21: =VLOOKUP(C21,'Parâmetros'!$D$2:$F$8,2,TRUE) | G21: % DE LIBERAÇÃO | I21: =VLOOKUP(C21,'Parâmetros'!$D$2:$F$8,3,TRUE)
A23: MÃO DE OBRA COM DEDICAÇÃO EXCLUSIVA
A24: Categoria/Cargo | C24: Postos | D24: Valor Unitário (do posto) | E24: Valor Mensal (postos × unitário) | F24: Horas Contratadas | G24: Qtd. de faltas (em horas) | H24: Valor da Hora | I24: Valor com desconto
A25: Paisagista | C25: 2 | D25: 9105.67 | E25: =C25*D25 | F25: =C25*'Parâmetros'!$I$2 | H25: =IF(F25=0,0,E25/F25) | I25: =H25*N(G25)
A26: Encarregado Geral | C26: 1 | D26: 4780.4 | E26: =C26*D26 | F26: =C26*'Parâmetros'!$I$2 | H26: =IF(F26=0,0,E26/F26) | I26: =H26*N(G26)
A27: Operador Motosserra | C27: 2 | D27: 5655.86 | E27: =C27*D27 | F27: =C27*'Parâmetros'!$I$2 | H27: =IF(F27=0,0,E27/F27) | I27: =H27*N(G27)
A28: Servente | C28: 3 | D28: 4116.24 | E28: =C28*D28 | F28: =C28*'Parâmetros'!$I$2 | H28: =IF(F28=0,0,E28/F28) | I28: =H28*N(G28)
A29: Arboricultor | C29: 1 | D29: 9243.63 | E29: =C29*D29 | F29: =C29*'Parâmetros'!$I$2 | H29: =IF(F29=0,0,E29/F29) | I29: =H29*N(G29)
A30: Jardineiro | C30: 3 | D30: 6391.83 | E30: =C30*D30 | F30: =C30*'Parâmetros'!$I$2 | H30: =IF(F30=0,0,E30/F30) | I30: =H30*N(G30)
A31: TOTAIS | C31: =SUM(C25:C30) | E31: =SUM(E25:E30) | F31: =SUM(F25:F30) | G31: =SUM(G25:G30) | I31: =SUM(I25:I30)
A33: REEMBOLSO DE CRECHE
A34: Qtde contratada | C34: Valor estimado unitário | D34: Valor retido (mensal) | E34: Reembolsos aprovados | F34: Valor por dependente | G34: Total dos reembolsos | H34: Saldo acumulado
A35: =C31 | C35: 129.29 | D35: =A35*C35 | E35: 0 | F35: 526.64 | G35: =E35*F35 | H35: =D35-G35
A36: Retido = qtde contratada × valor estimado unitário · Total = reembolsos aprovados × valor por dependente · Saldo = saldo do mês anterior + retido − total.
A38: APURAÇÃO DO VALOR A FATURAR
A39: MEDIÇÃO DOS SERVIÇOS | F39: VALOR LIBERADO PARA FATURAMENTO
A40: VALOR UNITÁRIO (planilha orçamentária) | D40: 0.69657774 | F40: Valor dos serviços
A41: Dias Trabalhados no mês | D41: 25 | F41: Percentual de liberação (nota obtida) | I41: =I21
A42: Qtde contratada (soma dos postos) | D42: =C31 | F42: Subtotal dos serviços | I42: =I40*I41
A43: Serviço de mão-de-obra (total mensal ÷ 30 × dias) | D43: =E31/'Parâmetros'!$I$3*D41 | F43: Valor do desconto (nota) | I43: =I42-I40
...

Sheet NOV-26
A1: UNIVERSIDADE FEDERAL DO RIO DE JANEIRO — PRÓ-REITORIA DE GESTÃO E GOVERNANÇA (PR-6)
A2: INSTRUMENTO DE MEDIÇÃO DE RESULTADO | H2: IMR Nº | I2: ='OUT-26'!I2
A3: OBJETO | B3: ='OUT-26'!B3
A4: EMPRESA | B4: ='OUT-26'!B4 | F4: CONTRATO | G4: ='OUT-26'!G4
A5: UNIDADE | B5: ='OUT-26'!B5 | F5: TERMO | G5: ='OUT-26'!G5
A6: MÊS/ANO | B6: =EDATE('OUT-26'!B6,1) | F6: FISCAL
A7: Preencha as células em amarelo. Pontuação, nota e valores são calculados automaticamente.
A8: AVALIAÇÃO DOS SERVIÇOS
A9: Cód. | B9: Indicador | G9: Avaliação correspondente | H9: Pontos | I9: Peso
A10: Módulo A — QUALIDADE DOS SERVIÇOS | I10: Peso 25
A11: A.1 | B11: CONFORMIDADE DOS EQUIPAMENTOS PARA EXECUÇÃO DOS SERVIÇOS | H11: =IFERROR(VLOOKUP(G11,'Parâmetros'!$A$2:$B$4,2,FALSE),0)
A12: A.2 | B12: CONFORMIDADE DOS SERVIÇOS EXECUTADOS COM AS ESPECIFICAÇÕES TÉCNICAS | H12: =IFERROR(VLOOKUP(G12,'Parâmetros'!$A$2:$B$4,2,FALSE),0)
A13: Pontuação total do Módulo A | H13: =SUM(H11:H12)
A14: Módulo B — EQUIPE DE TRABALHO | I14: Peso 25
A15: B.1 | B15: UNIFORMIZAÇÃO E EQUIPAMENTOS DE PROTEÇÃO INDIVIDUAL | H15: =IFERROR(VLOOKUP(G15,'Parâmetros'!$A$2:$B$4,2,FALSE),0)
A16: B.2 | B16: QUALIDADE DA EQUIPE | H16: =IFERROR(VLOOKUP(G16,'Parâmetros'!$A$2:$B$4,2,FALSE),0)
A17: Pontuação total do Módulo B | H17: =SUM(H15:H16)
A18: Módulo C — CUMPRIMENTO DO CRONOGRAMA | I18: Peso 25
A19: C.1 | B19: CUMPRIMENTO DO CRONOGRAMA E DAS ATIVIDADES | H19: =IFERROR(VLOOKUP(G19,'Parâmetros'!$A$2:$B$4,2,FALSE),0)
A20: Pontuação total do Módulo C | H20: =SUM(H19:H19)
A21: TOTAL DE PONTOS | C21: =(H11+H12+H15+H16+H19)/5 | D21: NOTA OBTIDA | F21: =VLOOKUP(C21,'Parâmetros'!$D$2:$F$8,2,TRUE) | G21: % DE LIBERAÇÃO | I21: =VLOOKUP(C21,'Parâmetros'!$D$2:$F$8,3,TRUE)
A23: MÃO DE OBRA COM DEDICAÇÃO EXCLUSIVA
A24: Categoria/Cargo | C24: Postos | D24: Valor Unitário (do posto) | E24: Valor Mensal (postos × unitário) | F24: Horas Contratadas | G24: Qtd. de faltas (em horas) | H24: Valor da Hora | I24: Valor com desconto
A25: ='OUT-26'!A25 | C25: ='OUT-26'!C25 | D25: ='OUT-26'!D25 | E25: =C25*D25 | F25: =C25*'Parâmetros'!$I$2 | H25: =IF(F25=0,0,E25/F25) | I25: =H25*N(G25)
A26: ='OUT-26'!A26 | C26: ='OUT-26'!C26 | D26: ='OUT-26'!D26 | E26: =C26*D26 | F26: =C26*'Parâmetros'!$I$2 | H26: =IF(F26=0,0,E26/F26) | I26: =H26*N(G26)
A27: ='OUT-26'!A27 | C27: ='OUT-26'!C27 | D27: ='OUT-26'!D27 | E27: =C27*D27 | F27: =C27*'Parâmetros'!$I$2 | H27: =IF(F27=0,0,E27/F27) | I27: =H27*N(G27)
A28: ='OUT-26'!A28 | C28: ='OUT-26'!C28 | D28: ='OUT-26'!D28 | E28: =C28*D28 | F28: =C28*'Parâmetros'!$I$2 | H28: =IF(F28=0,0,E28/F28) | I28: =H28*N(G28)
A29: ='OUT-26'!A29 | C29: ='OUT-26'!C29 | D29: ='OUT-26'!D29 | E29: =C29*D29 | F29: =C29*'Parâmetros'!$I$2 | H29: =IF(F29=0,0,E29/F29) | I29: =H29*N(G29)
A30: ='OUT-26'!A30 | C30: ='OUT-26'!C30 | D30: ='OUT-26'!D30 | E30: =C30*D30 | F30: =C30*'Parâmetros'!$I$2 | H30: =IF(F30=0,0,E30/F30) | I30: =H30*N(G30)
A31: TOTAIS | C31: =SUM(C25:C30) | E31: =SUM(E25:E30) | F31: =SUM(F25:F30) | G31: =SUM(G25:G30) | I31: =SUM(I25:I30)
A33: REEMBOLSO DE CRECHE
A34: Qtde contratada | C34: Valor estimado unitário | D34: Valor retido (mensal) | E34: Reembolsos aprovados | F34: Valor por dependente | G34: Total dos reembolsos | H34: Saldo acumulado
A35: =C31 | C35: ='OUT-26'!C35 | D35: =A35*C35 | E35: 0 | F35: ='OUT-26'!F35 | G35: =E35*F35 | H35: ='OUT-26'!H35+D35-G35
A36: Retido = qtde contratada × valor estimado unitário · Total = reembolsos aprovados × valor por dependente · Saldo = saldo do mês anterior + retido − total.
A38: APURAÇÃO DO VALOR A FATURAR
A39: MEDIÇÃO DOS SERVIÇOS | F39: VALOR LIBERADO PARA FATURAMENTO
A40: VALOR UNITÁRIO (planilha orçamentária) | D40: ='OUT-26'!D40 | F40: Valor dos serviços
A41: Dias Trabalhados no mês | D41: 25 | F41: Percentual de liberação (nota obtida) | I41: =I21
A42: Qtde contratada (soma dos postos) | D42: =C31 | F42: Subtotal dos serviços | I42: =I40*I41
A43: Serviço de mão-de-obra (total mensal ÷ 30 × dias) | D43: =E31/'Parâmetros'!$I$3*D41 | F43: Valor do desconto (nota) | I43: =I42-I40
...

Sheet DEZ-26
A1: UNIVERSIDADE FEDERAL DO RIO DE JANEIRO — PRÓ-REITORIA DE GESTÃO E GOVERNANÇA (PR-6)
A2: INSTRUMENTO DE MEDIÇÃO DE RESULTADO | H2: IMR Nº | I2: ='NOV-26'!I2
A3: OBJETO | B3: ='NOV-26'!B3
A4: EMPRESA | B4: ='NOV-26'!B4 | F4: CONTRATO | G4: ='NOV-26'!G4
A5: UNIDADE | B5: ='NOV-26'!B5 | F5: TERMO | G5: ='NOV-26'!G5
A6: MÊS/ANO | B6: =EDATE('NOV-26'!B6,1) | F6: FISCAL
A7: Preencha as células em amarelo. Pontuação, nota e valores são calculados automaticamente.
A8: AVALIAÇÃO DOS SERVIÇOS
A9: Cód. | B9: Indicador | G9: Avaliação correspondente | H9: Pontos | I9: Peso
A10: Módulo A — QUALIDADE DOS SERVIÇOS | I10: Peso 25
A11: A.1 | B11: CONFORMIDADE DOS EQUIPAMENTOS PARA EXECUÇÃO DOS SERVIÇOS | H11: =IFERROR(VLOOKUP(G11,'Parâmetros'!$A$2:$B$4,2,FALSE),0)
A12: A.2 | B12: CONFORMIDADE DOS SERVIÇOS EXECUTADOS COM AS ESPECIFICAÇÕES TÉCNICAS | H12: =IFERROR(VLOOKUP(G12,'Parâmetros'!$A$2:$B$4,2,FALSE),0)
A13: Pontuação total do Módulo A | H13: =SUM(H11:H12)
A14: Módulo B — EQUIPE DE TRABALHO | I14: Peso 25
A15: B.1 | B15: UNIFORMIZAÇÃO E EQUIPAMENTOS DE PROTEÇÃO INDIVIDUAL | H15: =IFERROR(VLOOKUP(G15,'Parâmetros'!$A$2:$B$4,2,FALSE),0)
A16: B.2 | B16: QUALIDADE DA EQUIPE | H16: =IFERROR(VLOOKUP(G16,'Parâmetros'!$A$2:$B$4,2,FALSE),0)
A17: Pontuação total do Módulo B | H17: =SUM(H15:H16)
A18: Módulo C — CUMPRIMENTO DO CRONOGRAMA | I18: Peso 25
A19: C.1 | B19: CUMPRIMENTO DO CRONOGRAMA E DAS ATIVIDADES | H19: =IFERROR(VLOOKUP(G19,'Parâmetros'!$A$2:$B$4,2,FALSE),0)
A20: Pontuação total do Módulo C | H20: =SUM(H19:H19)
A21: TOTAL DE PONTOS | C21: =(H11+H12+H15+H16+H19)/5 | D21: NOTA OBTIDA | F21: =VLOOKUP(C21,'Parâmetros'!$D$2:$F$8,2,TRUE) | G21: % DE LIBERAÇÃO | I21: =VLOOKUP(C21,'Parâmetros'!$D$2:$F$8,3,TRUE)
A23: MÃO DE OBRA COM DEDICAÇÃO EXCLUSIVA
A24: Categoria/Cargo | C24: Postos | D24: Valor Unitário (do posto) | E24: Valor Mensal (postos × unitário) | F24: Horas Contratadas | G24: Qtd. de faltas (em horas) | H24: Valor da Hora | I24: Valor com desconto
A25: ='NOV-26'!A25 | C25: ='NOV-26'!C25 | D25: ='NOV-26'!D25 | E25: =C25*D25 | F25: =C25*'Parâmetros'!$I$2 | H25: =IF(F25=0,0,E25/F25) | I25: =H25*N(G25)
A26: ='NOV-26'!A26 | C26: ='NOV-26'!C26 | D26: ='NOV-26'!D26 | E26: =C26*D26 | F26: =C26*'Parâmetros'!$I$2 | H26: =IF(F26=0,0,E26/F26) | I26: =H26*N(G26)
A27: ='NOV-26'!A27 | C27: ='NOV-26'!C27 | D27: ='NOV-26'!D27 | E27: =C27*D27 | F27: =C27*'Parâmetros'!$I$2 | H27: =IF(F27=0,0,E27/F27) | I27: =H27*N(G27)
A28: ='NOV-26'!A28 | C28: ='NOV-26'!C28 | D28: ='NOV-26'!D28 | E28: =C28*D28 | F28: =C28*'Parâmetros'!$I$2 | H28: =IF(F28=0,0,E28/F28) | I28: =H28*N(G28)
A29: ='NOV-26'!A29 | C29: ='NOV-26'!C29 | D29: ='NOV-26'!D29 | E29: =C29*D29 | F29: =C29*'Parâmetros'!$I$2 | H29: =IF(F29=0,0,E29/F29) | I29: =H29*N(G29)
A30: ='NOV-26'!A30 | C30: ='NOV-26'!C30 | D30: ='NOV-26'!D30 | E30: =C30*D30 | F30: =C30*'Parâmetros'!$I$2 | H30: =IF(F30=0,0,E30/F30) | I30: =H30*N(G30)
A31: TOTAIS | C31: =SUM(C25:C30) | E31: =SUM(E25:E30) | F31: =SUM(F25:F30) | G31: =SUM(G25:G30) | I31: =SUM(I25:I30)
A33: REEMBOLSO DE CRECHE
A34: Qtde contratada | C34: Valor estimado unitário | D34: Valor retido (mensal) | E34: Reembolsos aprovados | F34: Valor por dependente | G34: Total dos reembolsos | H34: Saldo acumulado
A35: =C31 | C35: ='NOV-26'!C35 | D35: =A35*C35 | E35: 0 | F35: ='NOV-26'!F35 | G35: =E35*F35 | H35: ='NOV-26'!H35+D35-G35
A36: Retido = qtde contratada × valor estimado unitário · Total = reembolsos aprovados × valor por dependente · Saldo = saldo do mês anterior + retido − total.
A38: APURAÇÃO DO VALOR A FATURAR
A39: MEDIÇÃO DOS SERVIÇOS | F39: VALOR LIBERADO PARA FATURAMENTO
A40: VALOR UNITÁRIO (planilha orçamentária) | D40: ='NOV-26'!D40 | F40: Valor dos serviços
A41: Dias Trabalhados no mês | D41: 25 | F41: Percentual de liberação (nota obtida) | I41: =I21
A42: Qtde contratada (soma dos postos) | D42: =C31 | F42: Subtotal dos serviços | I42: =I40*I41
A43: Serviço de mão-de-obra (total mensal ÷ 30 × dias) | D43: =E31/'Parâmetros'!$I$3*D41 | F43: Valor do desconto (nota) | I43: =I42-I40
...

Sheet JAN-27
A1: UNIVERSIDADE FEDERAL DO RIO DE JANEIRO — PRÓ-REITORIA DE GESTÃO E GOVERNANÇA (PR-6)
A2: INSTRUMENTO DE MEDIÇÃO DE RESULTADO | H2: IMR Nº | I2: ='DEZ-26'!I2
A3: OBJETO | B3: ='DEZ-26'!B3
A4: EMPRESA | B4: ='DEZ-26'!B4 | F4: CONTRATO | G4: ='DEZ-26'!G4
A5: UNIDADE | B5: ='DEZ-26'!B5 | F5: TERMO | G5: ='DEZ-26'!G5
A6: MÊS/ANO | B6: =EDATE('DEZ-26'!B6,1) | F6: FISCAL
A7: Preencha as células em amarelo. Pontuação, nota e valores são calculados automaticamente.
A8: AVALIAÇÃO DOS SERVIÇOS
A9: Cód. | B9: Indicador | G9: Avaliação correspondente | H9: Pontos | I9: Peso
A10: Módulo A — QUALIDADE DOS SERVIÇOS | I10: Peso 25
A11: A.1 | B11: CONFORMIDADE DOS EQUIPAMENTOS PARA EXECUÇÃO DOS SERVIÇOS | H11: =IFERROR(VLOOKUP(G11,'Parâmetros'!$A$2:$B$4,2,FALSE),0)
A12: A.2 | B12: CONFORMIDADE DOS SERVIÇOS EXECUTADOS COM AS ESPECIFICAÇÕES TÉCNICAS | H12: =IFERROR(VLOOKUP(G12,'Parâmetros'!$A$2:$B$4,2,FALSE),0)
A13: Pontuação total do Módulo A | H13: =SUM(H11:H12)
A14: Módulo B — EQUIPE DE TRABALHO | I14: Peso 25
A15: B.1 | B15: UNIFORMIZAÇÃO E EQUIPAMENTOS DE PROTEÇÃO INDIVIDUAL | H15: =IFERROR(VLOOKUP(G15,'Parâmetros'!$A$2:$B$4,2,FALSE),0)
A16: B.2 | B16: QUALIDADE DA EQUIPE | H16: =IFERROR(VLOOKUP(G16,'Parâmetros'!$A$2:$B$4,2,FALSE),0)
A17: Pontuação total do Módulo B | H17: =SUM(H15:H16)
A18: Módulo C — CUMPRIMENTO DO CRONOGRAMA | I18: Peso 25
A19: C.1 | B19: CUMPRIMENTO DO CRONOGRAMA E DAS ATIVIDADES | H19: =IFERROR(VLOOKUP(G19,'Parâmetros'!$A$2:$B$4,2,FALSE),0)
A20: Pontuação total do Módulo C | H20: =SUM(H19:H19)
A21: TOTAL DE PONTOS | C21: =(H11+H12+H15+H16+H19)/5 | D21: NOTA OBTIDA | F21: =VLOOKUP(C21,'Parâmetros'!$D$2:$F$8,2,TRUE) | G21: % DE LIBERAÇÃO | I21: =VLOOKUP(C21,'Parâmetros'!$D$2:$F$8,3,TRUE)
A23: MÃO DE OBRA COM DEDICAÇÃO EXCLUSIVA
A24: Categoria/Cargo | C24: Postos | D24: Valor Unitário (do posto) | E24: Valor Mensal (postos × unitário) | F24: Horas Contratadas | G24: Qtd. de faltas (em horas) | H24: Valor da Hora | I24: Valor com desconto
A25: ='DEZ-26'!A25 | C25: ='DEZ-26'!C25 | D25: ='DEZ-26'!D25 | E25: =C25*D25 | F25: =C25*'Parâmetros'!$I$2 | H25: =IF(F25=0,0,E25/F25) | I25: =H25*N(G25)
A26: ='DEZ-26'!A26 | C26: ='DEZ-26'!C26 | D26: ='DEZ-26'!D26 | E26: =C26*D26 | F26: =C26*'Parâmetros'!$I$2 | H26: =IF(F26=0,0,E26/F26) | I26: =H26*N(G26)
A27: ='DEZ-26'!A27 | C27: ='DEZ-26'!C27 | D27: ='DEZ-26'!D27 | E27: =C27*D27 | F27: =C27*'Parâmetros'!$I$2 | H27: =IF(F27=0,0,E27/F27) | I27: =H27*N(G27)
A28: ='DEZ-26'!A28 | C28: ='DEZ-26'!C28 | D28: ='DEZ-26'!D28 | E28: =C28*D28 | F28: =C28*'Parâmetros'!$I$2 | H28: =IF(F28=0,0,E28/F28) | I28: =H28*N(G28)
A29: ='DEZ-26'!A29 | C29: ='DEZ-26'!C29 | D29: ='DEZ-26'!D29 | E29: =C29*D29 | F29: =C29*'Parâmetros'!$I$2 | H29: =IF(F29=0,0,E29/F29) | I29: =H29*N(G29)
A30: ='DEZ-26'!A30 | C30: ='DEZ-26'!C30 | D30: ='DEZ-26'!D30 | E30: =C30*D30 | F30: =C30*'Parâmetros'!$I$2 | H30: =IF(F30=0,0,E30/F30) | I30: =H30*N(G30)
A31: TOTAIS | C31: =SUM(C25:C30) | E31: =SUM(E25:E30) | F31: =SUM(F25:F30) | G31: =SUM(G25:G30) | I31: =SUM(I25:I30)
A33: REEMBOLSO DE CRECHE
A34: Qtde contratada | C34: Valor estimado unitário | D34: Valor retido (mensal) | E34: Reembolsos aprovados | F34: Valor por dependente | G34: Total dos reembolsos | H34: Saldo acumulado
A35: =C31 | C35: ='DEZ-26'!C35 | D35: =A35*C35 | E35: 0 | F35: ='DEZ-26'!F35 | G35: =E35*F35 | H35: ='DEZ-26'!H35+D35-G35
A36: Retido = qtde contratada × valor estimado unitário · Total = reembolsos aprovados × valor por dependente · Saldo = saldo do mês anterior + retido − total.
A38: APURAÇÃO DO VALOR A FATURAR
A39: MEDIÇÃO DOS SERVIÇOS | F39: VALOR LIBERADO PARA FATURAMENTO
A40: VALOR UNITÁRIO (planilha orçamentária) | D40: ='DEZ-26'!D40 | F40: Valor dos serviços
A41: Dias Trabalhados no mês | D41: 25 | F41: Percentual de liberação (nota obtida) | I41: =I21
A42: Qtde contratada (soma dos postos) | D42: =C31 | F42: Subtotal dos serviços | I42: =I40*I41
A43: Serviço de mão-de-obra (total mensal ÷ 30 × dias) | D43: =E31/'Parâmetros'!$I$3*D41 | F43: Valor do desconto (nota) | I43: =I42-I40
...

Sheet FEV-27
A1: UNIVERSIDADE FEDERAL DO RIO DE JANEIRO — PRÓ-REITORIA DE GESTÃO E GOVERNANÇA (PR-6)
A2: INSTRUMENTO DE MEDIÇÃO DE RESULTADO | H2: IMR Nº | I2: ='JAN-27'!I2
A3: OBJETO | B3: ='JAN-27'!B3
A4: EMPRESA | B4: ='JAN-27'!B4 | F4: CONTRATO | G4: ='JAN-27'!G4
A5: UNIDADE | B5: ='JAN-27'!B5 | F5: TERMO | G5: ='JAN-27'!G5
A6: MÊS/ANO | B6: =EDATE('JAN-27'!B6,1) | F6: FISCAL
A7: Preencha as células em amarelo. Pontuação, nota e valores são calculados automaticamente.
A8: AVALIAÇÃO DOS SERVIÇOS
A9: Cód. | B9: Indicador | G9: Avaliação correspondente | H9: Pontos | I9: Peso
A10: Módulo A — QUALIDADE DOS SERVIÇOS | I10: Peso 25
A11: A.1 | B11: CONFORMIDADE DOS EQUIPAMENTOS PARA EXECUÇÃO DOS SERVIÇOS | H11: =IFERROR(VLOOKUP(G11,'Parâmetros'!$A$2:$B$4,2,FALSE),0)
A12: A.2 | B12: CONFORMIDADE DOS SERVIÇOS EXECUTADOS COM AS ESPECIFICAÇÕES TÉCNICAS | H12: =IFERROR(VLOOKUP(G12,'Parâmetros'!$A$2:$B$4,2,FALSE),0)
A13: Pontuação total do Módulo A | H13: =SUM(H11:H12)
A14: Módulo B — EQUIPE DE TRABALHO | I14: Peso 25
A15: B.1 | B15: UNIFORMIZAÇÃO E EQUIPAMENTOS DE PROTEÇÃO INDIVIDUAL | H15: =IFERROR(VLOOKUP(G15,'Parâmetros'!$A$2:$B$4,2,FALSE),0)
A16: B.2 | B16: QUALIDADE DA EQUIPE | H16: =IFERROR(VLOOKUP(G16,'Parâmetros'!$A$2:$B$4,2,FALSE),0)
A17: Pontuação total do Módulo B | H17: =SUM(H15:H16)
A18: Módulo C — CUMPRIMENTO DO CRONOGRAMA | I18: Peso 25
A19: C.1 | B19: CUMPRIMENTO DO CRONOGRAMA E DAS ATIVIDADES | H19: =IFERROR(VLOOKUP(G19,'Parâmetros'!$A$2:$B$4,2,FALSE),0)
A20: Pontuação total do Módulo C | H20: =SUM(H19:H19)
A21: TOTAL DE PONTOS | C21: =(H11+H12+H15+H16+H19)/5 | D21: NOTA OBTIDA | F21: =VLOOKUP(C21,'Parâmetros'!$D$2:$F$8,2,TRUE) | G21: % DE LIBERAÇÃO | I21: =VLOOKUP(C21,'Parâmetros'!$D$2:$F$8,3,TRUE)
A23: MÃO DE OBRA COM DEDICAÇÃO EXCLUSIVA
A24: Categoria/Cargo | C24: Postos | D24: Valor Unitário (do posto) | E24: Valor Mensal (postos × unitário) | F24: Horas Contratadas | G24: Qtd. de faltas (em horas) | H24: Valor da Hora | I24: Valor com desconto
A25: ='JAN-27'!A25 | C25: ='JAN-27'!C25 | D25: ='JAN-27'!D25 | E25: =C25*D25 | F25: =C25*'Parâmetros'!$I$2 | H25: =IF(F25=0,0,E25/F25) | I25: =H25*N(G25)
A26: ='JAN-27'!A26 | C26: ='JAN-27'!C26 | D26: ='JAN-27'!D26 | E26: =C26*D26 | F26: =C26*'Parâmetros'!$I$2 | H26: =IF(F26=0,0,E26/F26) | I26: =H26*N(G26)
A27: ='JAN-27'!A27 | C27: ='JAN-27'!C27 | D27: ='JAN-27'!D27 | E27: =C27*D27 | F27: =C27*'Parâmetros'!$I$2 | H27: =IF(F27=0,0,E27/F27) | I27: =H27*N(G27)
A28: ='JAN-27'!A28 | C28: ='JAN-27'!C28 | D28: ='JAN-27'!D28 | E28: =C28*D28 | F28: =C28*'Parâmetros'!$I$2 | H28: =IF(F28=0,0,E28/F28) | I28: =H28*N(G28)
A29: ='JAN-27'!A29 | C29: ='JAN-27'!C29 | D29: ='JAN-27'!D29 | E29: =C29*D29 | F29: =C29*'Parâmetros'!$I$2 | H29: =IF(F29=0,0,E29/F29) | I29: =H29*N(G29)
A30: ='JAN-27'!A30 | C30: ='JAN-27'!C30 | D30: ='JAN-27'!D30 | E30: =C30*D30 | F30: =C30*'Parâmetros'!$I$2 | H30: =IF(F30=0,0,E30/F30) | I30: =H30*N(G30)
A31: TOTAIS | C31: =SUM(C25:C30) | E31: =SUM(E25:E30) | F31: =SUM(F25:F30) | G31: =SUM(G25:G30) | I31: =SUM(I25:I30)
A33: REEMBOLSO DE CRECHE
A34: Qtde contratada | C34: Valor estimado unitário | D34: Valor retido (mensal) | E34: Reembolsos aprovados | F34: Valor por dependente | G34: Total dos reembolsos | H34: Saldo acumulado
A35: =C31 | C35: ='JAN-27'!C35 | D35: =A35*C35 | E35: 0 | F35: ='JAN-27'!F35 | G35: =E35*F35 | H35: ='JAN-27'!H35+D35-G35
A36: Retido = qtde contratada × valor estimado unitário · Total = reembolsos aprovados × valor por dependente · Saldo = saldo do mês anterior + retido − total.
A38: APURAÇÃO DO VALOR A FATURAR
A39: MEDIÇÃO DOS SERVIÇOS | F39: VALOR LIBERADO PARA FATURAMENTO
A40: VALOR UNITÁRIO (planilha orçamentária) | D40: ='JAN-27'!D40 | F40: Valor dos serviços
A41: Dias Trabalhados no mês | D41: 25 | F41: Percentual de liberação (nota obtida) | I41: =I21
A42: Qtde contratada (soma dos postos) | D42: =C31 | F42: Subtotal dos serviços | I42: =I40*I41
A43: Serviço de mão-de-obra (total mensal ÷ 30 × dias) | D43: =E31/'Parâmetros'!$I$3*D41 | F43: Valor do desconto (nota) | I43: =I42-I40
...

Sheet MAR-27
A1: UNIVERSIDADE FEDERAL DO RIO DE JANEIRO — PRÓ-REITORIA DE GESTÃO E GOVERNANÇA (PR-6)
A2: INSTRUMENTO DE MEDIÇÃO DE RESULTADO | H2: IMR Nº | I2: ='FEV-27'!I2
A3: OBJETO | B3: ='FEV-27'!B3
A4: EMPRESA | B4: ='FEV-27'!B4 | F4: CONTRATO | G4: ='FEV-27'!G4
A5: UNIDADE | B5: ='FEV-27'!B5 | F5: TERMO | G5: ='FEV-27'!G5
A6: MÊS/ANO | B6: =EDATE('FEV-27'!B6,1) | F6: FISCAL
A7: Preencha as células em amarelo. Pontuação, nota e valores são calculados automaticamente.
A8: AVALIAÇÃO DOS SERVIÇOS
A9: Cód. | B9: Indicador | G9: Avaliação correspondente | H9: Pontos | I9: Peso
A10: Módulo A — QUALIDADE DOS SERVIÇOS | I10: Peso 25
A11: A.1 | B11: CONFORMIDADE DOS EQUIPAMENTOS PARA EXECUÇÃO DOS SERVIÇOS | H11: =IFERROR(VLOOKUP(G11,'Parâmetros'!$A$2:$B$4,2,FALSE),0)
A12: A.2 | B12: CONFORMIDADE DOS SERVIÇOS EXECUTADOS COM AS ESPECIFICAÇÕES TÉCNICAS | H12: =IFERROR(VLOOKUP(G12,'Parâmetros'!$A$2:$B$4,2,FALSE),0)
A13: Pontuação total do Módulo A | H13: =SUM(H11:H12)
A14: Módulo B — EQUIPE DE TRABALHO | I14: Peso 25
A15: B.1 | B15: UNIFORMIZAÇÃO E EQUIPAMENTOS DE PROTEÇÃO INDIVIDUAL | H15: =IFERROR(VLOOKUP(G15,'Parâmetros'!$A$2:$B$4,2,FALSE),0)
A16: B.2 | B16: QUALIDADE DA EQUIPE | H16: =IFERROR(VLOOKUP(G16,'Parâmetros'!$A$2:$B$4,2,FALSE),0)
A17: Pontuação total do Módulo B | H17: =SUM(H15:H16)
A18: Módulo C — CUMPRIMENTO DO CRONOGRAMA | I18: Peso 25
A19: C.1 | B19: CUMPRIMENTO DO CRONOGRAMA E DAS ATIVIDADES | H19: =IFERROR(VLOOKUP(G19,'Parâmetros'!$A$2:$B$4,2,FALSE),0)
A20: Pontuação total do Módulo C | H20: =SUM(H19:H19)
A21: TOTAL DE PONTOS | C21: =(H11+H12+H15+H16+H19)/5 | D21: NOTA OBTIDA | F21: =VLOOKUP(C21,'Parâmetros'!$D$2:$F$8,2,TRUE) | G21: % DE LIBERAÇÃO | I21: =VLOOKUP(C21,'Parâmetros'!$D$2:$F$8,3,TRUE)
A23: MÃO DE OBRA COM DEDICAÇÃO EXCLUSIVA
A24: Categoria/Cargo | C24: Postos | D24: Valor Unitário (do posto) | E24: Valor Mensal (postos × unitário) | F24: Horas Contratadas | G24: Qtd. de faltas (em horas) | H24: Valor da Hora | I24: Valor com desconto
A25: ='FEV-27'!A25 | C25: ='FEV-27'!C25 | D25: ='FEV-27'!D25 | E25: =C25*D25 | F25: =C25*'Parâmetros'!$I$2 | H25: =IF(F25=0,0,E25/F25) | I25: =H25*N(G25)
A26: ='FEV-27'!A26 | C26: ='FEV-27'!C26 | D26: ='FEV-27'!D26 | E26: =C26*D26 | F26: =C26*'Parâmetros'!$I$2 | H26: =IF(F26=0,0,E26/F26) | I26: =H26*N(G26)
A27: ='FEV-27'!A27 | C27: ='FEV-27'!C27 | D27: ='FEV-27'!D27 | E27: =C27*D27 | F27: =C27*'Parâmetros'!$I$2 | H27: =IF(F27=0,0,E27/F27) | I27: =H27*N(G27)
A28: ='FEV-27'!A28 | C28: ='FEV-27'!C28 | D28: ='FEV-27'!D28 | E28: =C28*D28 | F28: =C28*'Parâmetros'!$I$2 | H28: =IF(F28=0,0,E28/F28) | I28: =H28*N(G28)
A29: ='FEV-27'!A29 | C29: ='FEV-27'!C29 | D29: ='FEV-27'!D29 | E29: =C29*D29 | F29: =C29*'Parâmetros'!$I$2 | H29: =IF(F29=0,0,E29/F29) | I29: =H29*N(G29)
A30: ='FEV-27'!A30 | C30: ='FEV-27'!C30 | D30: ='FEV-27'!D30 | E30: =C30*D30 | F30: =C30*'Parâmetros'!$I$2 | H30: =IF(F30=0,0,E30/F30) | I30: =H30*N(G30)
A31: TOTAIS | C31: =SUM(C25:C30) | E31: =SUM(E25:E30) | F31: =SUM(F25:F30) | G31: =SUM(G25:G30) | I31: =SUM(I25:I30)
A33: REEMBOLSO DE CRECHE
A34: Qtde contratada | C34: Valor estimado unitário | D34: Valor retido (mensal) | E34: Reembolsos aprovados | F34: Valor por dependente | G34: Total dos reembolsos | H34: Saldo acumulado
A35: =C31 | C35: ='FEV-27'!C35 | D35: =A35*C35 | E35: 0 | F35: ='FEV-27'!F35 | G35: =E35*F35 | H35: ='FEV-27'!H35+D35-G35
A36: Retido = qtde contratada × valor estimado unitário · Total = reembolsos aprovados × valor por dependente · Saldo = saldo do mês anterior + retido − total.
A38: APURAÇÃO DO VALOR A FATURAR
A39: MEDIÇÃO DOS SERVIÇOS | F39: VALOR LIBERADO PARA FATURAMENTO
A40: VALOR UNITÁRIO (planilha orçamentária) | D40: ='FEV-27'!D40 | F40: Valor dos serviços
A41: Dias Trabalhados no mês | D41: 25 | F41: Percentual de liberação (nota obtida) | I41: =I21
A42: Qtde contratada (soma dos postos) | D42: =C31 | F42: Subtotal dos serviços | I42: =I40*I41
A43: Serviço de mão-de-obra (total mensal ÷ 30 × dias) | D43: =E31/'Parâmetros'!$I$3*D41 | F43: Valor do desconto (nota) | I43: =I42-I40
...

Sheet ABR-27
A1: UNIVERSIDADE FEDERAL DO RIO DE JANEIRO — PRÓ-REITORIA DE GESTÃO E GOVERNANÇA (PR-6)
A2: INSTRUMENTO DE MEDIÇÃO DE RESULTADO | H2: IMR Nº | I2: ='MAR-27'!I2
A3: OBJETO | B3: ='MAR-27'!B3
A4: EMPRESA | B4: ='MAR-27'!B4 | F4: CONTRATO | G4: ='MAR-27'!G4
A5: UNIDADE | B5: ='MAR-27'!B5 | F5: TERMO | G5: ='MAR-27'!G5
A6: MÊS/ANO | B6: =EDATE('MAR-27'!B6,1) | F6: FISCAL
A7: Preencha as células em amarelo. Pontuação, nota e valores são calculados automaticamente.
A8: AVALIAÇÃO DOS SERVIÇOS
A9: Cód. | B9: Indicador | G9: Avaliação correspondente | H9: Pontos | I9: Peso
A10: Módulo A — QUALIDADE DOS SERVIÇOS | I10: Peso 25
A11: A.1 | B11: CONFORMIDADE DOS EQUIPAMENTOS PARA EXECUÇÃO DOS SERVIÇOS | H11: =IFERROR(VLOOKUP(G11,'Parâmetros'!$A$2:$B$4,2,FALSE),0)
A12: A.2 | B12: CONFORMIDADE DOS SERVIÇOS EXECUTADOS COM AS ESPECIFICAÇÕES TÉCNICAS | H12: =IFERROR(VLOOKUP(G12,'Parâmetros'!$A$2:$B$4,2,FALSE),0)
A13: Pontuação total do Módulo A | H13: =SUM(H11:H12)
A14: Módulo B — EQUIPE DE TRABALHO | I14: Peso 25
A15: B.1 | B15: UNIFORMIZAÇÃO E EQUIPAMENTOS DE PROTEÇÃO INDIVIDUAL | H15: =IFERROR(VLOOKUP(G15,'Parâmetros'!$A$2:$B$4,2,FALSE),0)
A16: B.2 | B16: QUALIDADE DA EQUIPE | H16: =IFERROR(VLOOKUP(G16,'Parâmetros'!$A$2:$B$4,2,FALSE),0)
A17: Pontuação total do Módulo B | H17: =SUM(H15:H16)
A18: Módulo C — CUMPRIMENTO DO CRONOGRAMA | I18: Peso 25
A19: C.1 | B19: CUMPRIMENTO DO CRONOGRAMA E DAS ATIVIDADES | H19: =IFERROR(VLOOKUP(G19,'Parâmetros'!$A$2:$B$4,2,FALSE),0)
A20: Pontuação total do Módulo C | H20: =SUM(H19:H19)
A21: TOTAL DE PONTOS | C21: =(H11+H12+H15+H16+H19)/5 | D21: NOTA OBTIDA | F21: =VLOOKUP(C21,'Parâmetros'!$D$2:$F$8,2,TRUE) | G21: % DE LIBERAÇÃO | I21: =VLOOKUP(C21,'Parâmetros'!$D$2:$F$8,3,TRUE)
A23: MÃO DE OBRA COM DEDICAÇÃO EXCLUSIVA
A24: Categoria/Cargo | C24: Postos | D24: Valor Unitário (do posto) | E24: Valor Mensal (postos × unitário) | F24: Horas Contratadas | G24: Qtd. de faltas (em horas) | H24: Valor da Hora | I24: Valor com desconto
A25: ='MAR-27'!A25 | C25: ='MAR-27'!C25 | D25: ='MAR-27'!D25 | E25: =C25*D25 | F25: =C25*'Parâmetros'!$I$2 | H25: =IF(F25=0,0,E25/F25) | I25: =H25*N(G25)
A26: ='MAR-27'!A26 | C26: ='MAR-27'!C26 | D26: ='MAR-27'!D26 | E26: =C26*D26 | F26: =C26*'Parâmetros'!$I$2 | H26: =IF(F26=0,0,E26/F26) | I26: =H26*N(G26)
A27: ='MAR-27'!A27 | C27: ='MAR-27'!C27 | D27: ='MAR-27'!D27 | E27: =C27*D27 | F27: =C27*'Parâmetros'!$I$2 | H27: =IF(F27=0,0,E27/F27) | I27: =H27*N(G27)
A28: ='MAR-27'!A28 | C28: ='MAR-27'!C28 | D28: ='MAR-27'!D28 | E28: =C28*D28 | F28: =C28*'Parâmetros'!$I$2 | H28: =IF(F28=0,0,E28/F28) | I28: =H28*N(G28)
A29: ='MAR-27'!A29 | C29: ='MAR-27'!C29 | D29: ='MAR-27'!D29 | E29: =C29*D29 | F29: =C29*'Parâmetros'!$I$2 | H29: =IF(F29=0,0,E29/F29) | I29: =H29*N(G29)
A30: ='MAR-27'!A30 | C30: ='MAR-27'!C30 | D30: ='MAR-27'!D30 | E30: =C30*D30 | F30: =C30*'Parâmetros'!$I$2 | H30: =IF(F30=0,0,E30/F30) | I30: =H30*N(G30)
A31: TOTAIS | C31: =SUM(C25:C30) | E31: =SUM(E25:E30) | F31: =SUM(F25:F30) | G31: =SUM(G25:G30) | I31: =SUM(I25:I30)
A33: REEMBOLSO DE CRECHE
A34: Qtde contratada | C34: Valor estimado unitário | D34: Valor retido (mensal) | E34: Reembolsos aprovados | F34: Valor por dependente | G34: Total dos reembolsos | H34: Saldo acumulado
A35: =C31 | C35: ='MAR-27'!C35 | D35: =A35*C35 | E35: 0 | F35: ='MAR-27'!F35 | G35: =E35*F35 | H35: ='MAR-27'!H35+D35-G35
A36: Retido = qtde contratada × valor estimado unitário · Total = reembolsos aprovados × valor por dependente · Saldo = saldo do mês anterior + retido − total.
A38: APURAÇÃO DO VALOR A FATURAR
A39: MEDIÇÃO DOS SERVIÇOS | F39: VALOR LIBERADO PARA FATURAMENTO
A40: VALOR UNITÁRIO (planilha orçamentária) | D40: ='MAR-27'!D40 | F40: Valor dos serviços
A41: Dias Trabalhados no mês | D41: 25 | F41: Percentual de liberação (nota obtida) | I41: =I21
A42: Qtde contratada (soma dos postos) | D42: =C31 | F42: Subtotal dos serviços | I42: =I40*I41
A43: Serviço de mão-de-obra (total mensal ÷ 30 × dias) | D43: =E31/'Parâmetros'!$I$3*D41 | F43: Valor do desconto (nota) | I43: =I42-I40
...

Sheet MAI-27
A1: UNIVERSIDADE FEDERAL DO RIO DE JANEIRO — PRÓ-REITORIA DE GESTÃO E GOVERNANÇA (PR-6)
A2: INSTRUMENTO DE MEDIÇÃO DE RESULTADO | H2: IMR Nº | I2: ='ABR-27'!I2
A3: OBJETO | B3: ='ABR-27'!B3
A4: EMPRESA | B4: ='ABR-27'!B4 | F4: CONTRATO | G4: ='ABR-27'!G4
A5: UNIDADE | B5: ='ABR-27'!B5 | F5: TERMO | G5: ='ABR-27'!G5
A6: MÊS/ANO | B6: =EDATE('ABR-27'!B6,1) | F6: FISCAL
A7: Preencha as células em amarelo. Pontuação, nota e valores são calculados automaticamente.
A8: AVALIAÇÃO DOS SERVIÇOS
A9: Cód. | B9: Indicador | G9: Avaliação correspondente | H9: Pontos | I9: Peso
A10: Módulo A — QUALIDADE DOS SERVIÇOS | I10: Peso 25
A11: A.1 | B11: CONFORMIDADE DOS EQUIPAMENTOS PARA EXECUÇÃO DOS SERVIÇOS | H11: =IFERROR(VLOOKUP(G11,'Parâmetros'!$A$2:$B$4,2,FALSE),0)
A12: A.2 | B12: CONFORMIDADE DOS SERVIÇOS EXECUTADOS COM AS ESPECIFICAÇÕES TÉCNICAS | H12: =IFERROR(VLOOKUP(G12,'Parâmetros'!$A$2:$B$4,2,FALSE),0)
A13: Pontuação total do Módulo A | H13: =SUM(H11:H12)
A14: Módulo B — EQUIPE DE TRABALHO | I14: Peso 25
A15: B.1 | B15: UNIFORMIZAÇÃO E EQUIPAMENTOS DE PROTEÇÃO INDIVIDUAL | H15: =IFERROR(VLOOKUP(G15,'Parâmetros'!$A$2:$B$4,2,FALSE),0)
A16: B.2 | B16: QUALIDADE DA EQUIPE | H16: =IFERROR(VLOOKUP(G16,'Parâmetros'!$A$2:$B$4,2,FALSE),0)
A17: Pontuação total do Módulo B | H17: =SUM(H15:H16)
A18: Módulo C — CUMPRIMENTO DO CRONOGRAMA | I18: Peso 25
A19: C.1 | B19: CUMPRIMENTO DO CRONOGRAMA E DAS ATIVIDADES | H19: =IFERROR(VLOOKUP(G19,'Parâmetros'!$A$2:$B$4,2,FALSE),0)
A20: Pontuação total do Módulo C | H20: =SUM(H19:H19)
A21: TOTAL DE PONTOS | C21: =(H11+H12+H15+H16+H19)/5 | D21: NOTA OBTIDA | F21: =VLOOKUP(C21,'Parâmetros'!$D$2:$F$8,2,TRUE) | G21: % DE LIBERAÇÃO | I21: =VLOOKUP(C21,'Parâmetros'!$D$2:$F$8,3,TRUE)
A23: MÃO DE OBRA COM DEDICAÇÃO EXCLUSIVA
A24: Categoria/Cargo | C24: Postos | D24: Valor Unitário (do posto) | E24: Valor Mensal (postos × unitário) | F24: Horas Contratadas | G24: Qtd. de faltas (em horas) | H24: Valor da Hora | I24: Valor com desconto
A25: ='ABR-27'!A25 | C25: ='ABR-27'!C25 | D25: ='ABR-27'!D25 | E25: =C25*D25 | F25: =C25*'Parâmetros'!$I$2 | H25: =IF(F25=0,0,E25/F25) | I25: =H25*N(G25)
A26: ='ABR-27'!A26 | C26: ='ABR-27'!C26 | D26: ='ABR-27'!D26 | E26: =C26*D26 | F26: =C26*'Parâmetros'!$I$2 | H26: =IF(F26=0,0,E26/F26) | I26: =H26*N(G26)
A27: ='ABR-27'!A27 | C27: ='ABR-27'!C27 | D27: ='ABR-27'!D27 | E27: =C27*D27 | F27: =C27*'Parâmetros'!$I$2 | H27: =IF(F27=0,0,E27/F27) | I27: =H27*N(G27)
A28: ='ABR-27'!A28 | C28: ='ABR-27'!C28 | D28: ='ABR-27'!D28 | E28: =C28*D28 | F28: =C28*'Parâmetros'!$I$2 | H28: =IF(F28=0,0,E28/F28) | I28: =H28*N(G28)
A29: ='ABR-27'!A29 | C29: ='ABR-27'!C29 | D29: ='ABR-27'!D29 | E29: =C29*D29 | F29: =C29*'Parâmetros'!$I$2 | H29: =IF(F29=0,0,E29/F29) | I29: =H29*N(G29)
A30: ='ABR-27'!A30 | C30: ='ABR-27'!C30 | D30: ='ABR-27'!D30 | E30: =C30*D30 | F30: =C30*'Parâmetros'!$I$2 | H30: =IF(F30=0,0,E30/F30) | I30: =H30*N(G30)
A31: TOTAIS | C31: =SUM(C25:C30) | E31: =SUM(E25:E30) | F31: =SUM(F25:F30) | G31: =SUM(G25:G30) | I31: =SUM(I25:I30)
A33: REEMBOLSO DE CRECHE
A34: Qtde contratada | C34: Valor estimado unitário | D34: Valor retido (mensal) | E34: Reembolsos aprovados | F34: Valor por dependente | G34: Total dos reembolsos | H34: Saldo acumulado
A35: =C31 | C35: ='ABR-27'!C35 | D35: =A35*C35 | E35: 0 | F35: ='ABR-27'!F35 | G35: =E35*F35 | H35: ='ABR-27'!H35+D35-G35
A36: Retido = qtde contratada × valor estimado unitário · Total = reembolsos aprovados × valor por dependente · Saldo = saldo do mês anterior + retido − total.
A38: APURAÇÃO DO VALOR A FATURAR
A39: MEDIÇÃO DOS SERVIÇOS | F39: VALOR LIBERADO PARA FATURAMENTO
A40: VALOR UNITÁRIO (planilha orçamentária) | D40: ='ABR-27'!D40 | F40: Valor dos serviços
A41: Dias Trabalhados no mês | D41: 25 | F41: Percentual de liberação (nota obtida) | I41: =I21
A42: Qtde contratada (soma dos postos) | D42: =C31 | F42: Subtotal dos serviços | I42: =I40*I41
A43: Serviço de mão-de-obra (total mensal ÷ 30 × dias) | D43: =E31/'Parâmetros'!$I$3*D41 | F43: Valor do desconto (nota) | I43: =I42-I40
...

Sheet JUN-27
A1: UNIVERSIDADE FEDERAL DO RIO DE JANEIRO — PRÓ-REITORIA DE GESTÃO E GOVERNANÇA (PR-6)
A2: INSTRUMENTO DE MEDIÇÃO DE RESULTADO | H2: IMR Nº | I2: ='MAI-27'!I2
A3: OBJETO | B3: ='MAI-27'!B3
A4: EMPRESA | B4: ='MAI-27'!B4 | F4: CONTRATO | G4: ='MAI-27'!G4
A5: UNIDADE | B5: ='MAI-27'!B5 | F5: TERMO | G5: ='MAI-27'!G5
A6: MÊS/ANO | B6: =EDATE('MAI-27'!B6,1) | F6: FISCAL
A7: Preencha as células em amarelo. Pontuação, nota e valores são calculados automaticamente.
A8: AVALIAÇÃO DOS SERVIÇOS
A9: Cód. | B9: Indicador | G9: Avaliação correspondente | H9: Pontos | I9: Peso
A10: Módulo A — QUALIDADE DOS SERVIÇOS | I10: Peso 25
A11: A.1 | B11: CONFORMIDADE DOS EQUIPAMENTOS PARA EXECUÇÃO DOS SERVIÇOS | H11: =IFERROR(VLOOKUP(G11,'Parâmetros'!$A$2:$B$4,2,FALSE),0)
A12: A.2 | B12: CONFORMIDADE DOS SERVIÇOS EXECUTADOS COM AS ESPECIFICAÇÕES TÉCNICAS | H12: =IFERROR(VLOOKUP(G12,'Parâmetros'!$A$2:$B$4,2,FALSE),0)
A13: Pontuação total do Módulo A | H13: =SUM(H11:H12)
A14: Módulo B — EQUIPE DE TRABALHO | I14: Peso 25
A15: B.1 | B15: UNIFORMIZAÇÃO E EQUIPAMENTOS DE PROTEÇÃO INDIVIDUAL | H15: =IFERROR(VLOOKUP(G15,'Parâmetros'!$A$2:$B$4,2,FALSE),0)
A16: B.2 | B16: QUALIDADE DA EQUIPE | H16: =IFERROR(VLOOKUP(G16,'Parâmetros'!$A$2:$B$4,2,FALSE),0)
A17: Pontuação total do Módulo B | H17: =SUM(H15:H16)
A18: Módulo C — CUMPRIMENTO DO CRONOGRAMA | I18: Peso 25
A19: C.1 | B19: CUMPRIMENTO DO CRONOGRAMA E DAS ATIVIDADES | H19: =IFERROR(VLOOKUP(G19,'Parâmetros'!$A$2:$B$4,2,FALSE),0)
A20: Pontuação total do Módulo C | H20: =SUM(H19:H19)
A21: TOTAL DE PONTOS | C21: =(H11+H12+H15+H16+H19)/5 | D21: NOTA OBTIDA | F21: =VLOOKUP(C21,'Parâmetros'!$D$2:$F$8,2,TRUE) | G21: % DE LIBERAÇÃO | I21: =VLOOKUP(C21,'Parâmetros'!$D$2:$F$8,3,TRUE)
A23: MÃO DE OBRA COM DEDICAÇÃO EXCLUSIVA
A24: Categoria/Cargo | C24: Postos | D24: Valor Unitário (do posto) | E24: Valor Mensal (postos × unitário) | F24: Horas Contratadas | G24: Qtd. de faltas (em horas) | H24: Valor da Hora | I24: Valor com desconto
A25: ='MAI-27'!A25 | C25: ='MAI-27'!C25 | D25: ='MAI-27'!D25 | E25: =C25*D25 | F25: =C25*'Parâmetros'!$I$2 | H25: =IF(F25=0,0,E25/F25) | I25: =H25*N(G25)
A26: ='MAI-27'!A26 | C26: ='MAI-27'!C26 | D26: ='MAI-27'!D26 | E26: =C26*D26 | F26: =C26*'Parâmetros'!$I$2 | H26: =IF(F26=0,0,E26/F26) | I26: =H26*N(G26)
A27: ='MAI-27'!A27 | C27: ='MAI-27'!C27 | D27: ='MAI-27'!D27 | E27: =C27*D27 | F27: =C27*'Parâmetros'!$I$2 | H27: =IF(F27=0,0,E27/F27) | I27: =H27*N(G27)
A28: ='MAI-27'!A28 | C28: ='MAI-27'!C28 | D28: ='MAI-27'!D28 | E28: =C28*D28 | F28: =C28*'Parâmetros'!$I$2 | H28: =IF(F28=0,0,E28/F28) | I28: =H28*N(G28)
A29: ='MAI-27'!A29 | C29: ='MAI-27'!C29 | D29: ='MAI-27'!D29 | E29: =C29*D29 | F29: =C29*'Parâmetros'!$I$2 | H29: =IF(F29=0,0,E29/F29) | I29: =H29*N(G29)
A30: ='MAI-27'!A30 | C30: ='MAI-27'!C30 | D30: ='MAI-27'!D30 | E30: =C30*D30 | F30: =C30*'Parâmetros'!$I$2 | H30: =IF(F30=0,0,E30/F30) | I30: =H30*N(G30)
A31: TOTAIS | C31: =SUM(C25:C30) | E31: =SUM(E25:E30) | F31: =SUM(F25:F30) | G31: =SUM(G25:G30) | I31: =SUM(I25:I30)
A33: REEMBOLSO DE CRECHE
A34: Qtde contratada | C34: Valor estimado unitário | D34: Valor retido (mensal) | E34: Reembolsos aprovados | F34: Valor por dependente | G34: Total dos reembolsos | H34: Saldo acumulado
A35: =C31 | C35: ='MAI-27'!C35 | D35: =A35*C35 | E35: 0 | F35: ='MAI-27'!F35 | G35: =E35*F35 | H35: ='MAI-27'!H35+D35-G35
A36: Retido = qtde contratada × valor estimado unitário · Total = reembolsos aprovados × valor por dependente · Saldo = saldo do mês anterior + retido − total.
A38: APURAÇÃO DO VALOR A FATURAR
A39: MEDIÇÃO DOS SERVIÇOS | F39: VALOR LIBERADO PARA FATURAMENTO
A40: VALOR UNITÁRIO (planilha orçamentária) | D40: ='MAI-27'!D40 | F40: Valor dos serviços
A41: Dias Trabalhados no mês | D41: 25 | F41: Percentual de liberação (nota obtida) | I41: =I21
A42: Qtde contratada (soma dos postos) | D42: =C31 | F42: Subtotal dos serviços | I42: =I40*I41
A43: Serviço de mão-de-obra (total mensal ÷ 30 × dias) | D43: =E31/'Parâmetros'!$I$3*D41 | F43: Valor do desconto (nota) | I43: =I42-I40
...

Sheet JUL-27
A1: UNIVERSIDADE FEDERAL DO RIO DE JANEIRO — PRÓ-REITORIA DE GESTÃO E GOVERNANÇA (PR-6)
A2: INSTRUMENTO DE MEDIÇÃO DE RESULTADO | H2: IMR Nº | I2: ='JUN-27'!I2
A3: OBJETO | B3: ='JUN-27'!B3
A4: EMPRESA | B4: ='JUN-27'!B4 | F4: CONTRATO | G4: ='JUN-27'!G4
A5: UNIDADE | B5: ='JUN-27'!B5 | F5: TERMO | G5: ='JUN-27'!G5
A6: MÊS/ANO | B6: =EDATE('JUN-27'!B6,1) | F6: FISCAL
A7: Preencha as células em amarelo. Pontuação, nota e valores são calculados automaticamente.
A8: AVALIAÇÃO DOS SERVIÇOS
A9: Cód. | B9: Indicador | G9: Avaliação correspondente | H9: Pontos | I9: Peso
A10: Módulo A — QUALIDADE DOS SERVIÇOS | I10: Peso 25
A11: A.1 | B11: CONFORMIDADE DOS EQUIPAMENTOS PARA EXECUÇÃO DOS SERVIÇOS | H11: =IFERROR(VLOOKUP(G11,'Parâmetros'!$A$2:$B$4,2,FALSE),0)
A12: A.2 | B12: CONFORMIDADE DOS SERVIÇOS EXECUTADOS COM AS ESPECIFICAÇÕES TÉCNICAS | H12: =IFERROR(VLOOKUP(G12,'Parâmetros'!$A$2:$B$4,2,FALSE),0)
A13: Pontuação total do Módulo A | H13: =SUM(H11:H12)
A14: Módulo B — EQUIPE DE TRABALHO | I14: Peso 25
A15: B.1 | B15: UNIFORMIZAÇÃO E EQUIPAMENTOS DE PROTEÇÃO INDIVIDUAL | H15: =IFERROR(VLOOKUP(G15,'Parâmetros'!$A$2:$B$4,2,FALSE),0)
A16: B.2 | B16: QUALIDADE DA EQUIPE | H16: =IFERROR(VLOOKUP(G16,'Parâmetros'!$A$2:$B$4,2,FALSE),0)
A17: Pontuação total do Módulo B | H17: =SUM(H15:H16)
A18: Módulo C — CUMPRIMENTO DO CRONOGRAMA | I18: Peso 25
A19: C.1 | B19: CUMPRIMENTO DO CRONOGRAMA E DAS ATIVIDADES | H19: =IFERROR(VLOOKUP(G19,'Parâmetros'!$A$2:$B$4,2,FALSE),0)
A20: Pontuação total do Módulo C | H20: =SUM(H19:H19)
A21: TOTAL DE PONTOS | C21: =(H11+H12+H15+H16+H19)/5 | D21: NOTA OBTIDA | F21: =VLOOKUP(C21,'Parâmetros'!$D$2:$F$8,2,TRUE) | G21: % DE LIBERAÇÃO | I21: =VLOOKUP(C21,'Parâmetros'!$D$2:$F$8,3,TRUE)
A23: MÃO DE OBRA COM DEDICAÇÃO EXCLUSIVA
A24: Categoria/Cargo | C24: Postos | D24: Valor Unitário (do posto) | E24: Valor Mensal (postos × unitário) | F24: Horas Contratadas | G24: Qtd. de faltas (em horas) | H24: Valor da Hora | I24: Valor com desconto
A25: ='JUN-27'!A25 | C25: ='JUN-27'!C25 | D25: ='JUN-27'!D25 | E25: =C25*D25 | F25: =C25*'Parâmetros'!$I$2 | H25: =IF(F25=0,0,E25/F25) | I25: =H25*N(G25)
A26: ='JUN-27'!A26 | C26: ='JUN-27'!C26 | D26: ='JUN-27'!D26 | E26: =C26*D26 | F26: =C26*'Parâmetros'!$I$2 | H26: =IF(F26=0,0,E26/F26) | I26: =H26*N(G26)
A27: ='JUN-27'!A27 | C27: ='JUN-27'!C27 | D27: ='JUN-27'!D27 | E27: =C27*D27 | F27: =C27*'Parâmetros'!$I$2 | H27: =IF(F27=0,0,E27/F27) | I27: =H27*N(G27)
A28: ='JUN-27'!A28 | C28: ='JUN-27'!C28 | D28: ='JUN-27'!D28 | E28: =C28*D28 | F28: =C28*'Parâmetros'!$I$2 | H28: =IF(F28=0,0,E28/F28) | I28: =H28*N(G28)
A29: ='JUN-27'!A29 | C29: ='JUN-27'!C29 | D29: ='JUN-27'!D29 | E29: =C29*D29 | F29: =C29*'Parâmetros'!$I$2 | H29: =IF(F29=0,0,E29/F29) | I29: =H29*N(G29)
A30: ='JUN-27'!A30 | C30: ='JUN-27'!C30 | D30: ='JUN-27'!D30 | E30: =C30*D30 | F30: =C30*'Parâmetros'!$I$2 | H30: =IF(F30=0,0,E30/F30) | I30: =H30*N(G30)
A31: TOTAIS | C31: =SUM(C25:C30) | E31: =SUM(E25:E30) | F31: =SUM(F25:F30) | G31: =SUM(G25:G30) | I31: =SUM(I25:I30)
A33: REEMBOLSO DE CRECHE
A34: Qtde contratada | C34: Valor estimado unitário | D34: Valor retido (mensal) | E34: Reembolsos aprovados | F34: Valor por dependente | G34: Total dos reembolsos | H34: Saldo acumulado
A35: =C31 | C35: ='JUN-27'!C35 | D35: =A35*C35 | E35: 0 | F35: ='JUN-27'!F35 | G35: =E35*F35 | H35: ='JUN-27'!H35+D35-G35
A36: Retido = qtde contratada × valor estimado unitário · Total = reembolsos aprovados × valor por dependente · Saldo = saldo do mês anterior + retido − total.
A38: APURAÇÃO DO VALOR A FATURAR
A39: MEDIÇÃO DOS SERVIÇOS | F39: VALOR LIBERADO PARA FATURAMENTO
A40: VALOR UNITÁRIO (planilha orçamentária) | D40: ='JUN-27'!D40 | F40: Valor dos serviços
A41: Dias Trabalhados no mês | D41: 25 | F41: Percentual de liberação (nota obtida) | I41: =I21
A42: Qtde contratada (soma dos postos) | D42: =C31 | F42: Subtotal dos serviços | I42: =I40*I41
A43: Serviço de mão-de-obra (total mensal ÷ 30 × dias) | D43: =E31/'Parâmetros'!$I$3*D41 | F43: Valor do desconto (nota) | I43: =I42-I40
...

Sheet AGO-27
A1: UNIVERSIDADE FEDERAL DO RIO DE JANEIRO — PRÓ-REITORIA DE GESTÃO E GOVERNANÇA (PR-6)
A2: INSTRUMENTO DE MEDIÇÃO DE RESULTADO | H2: IMR Nº | I2: ='JUL-27'!I2
A3: OBJETO | B3: ='JUL-27'!B3
A4: EMPRESA | B4: ='JUL-27'!B4 | F4: CONTRATO | G4: ='JUL-27'!G4
A5: UNIDADE | B5: ='JUL-27'!B5 | F5: TERMO | G5: ='JUL-27'!G5
A6: MÊS/ANO | B6: =EDATE('JUL-27'!B6,1) | F6: FISCAL
A7: Preencha as células em amarelo. Pontuação, nota e valores são calculados automaticamente.
A8: AVALIAÇÃO DOS SERVIÇOS
A9: Cód. | B9: Indicador | G9: Avaliação correspondente | H9: Pontos | I9: Peso
A10: Módulo A — QUALIDADE DOS SERVIÇOS | I10: Peso 25
A11: A.1 | B11: CONFORMIDADE DOS EQUIPAMENTOS PARA EXECUÇÃO DOS SERVIÇOS | H11: =IFERROR(VLOOKUP(G11,'Parâmetros'!$A$2:$B$4,2,FALSE),0)
A12: A.2 | B12: CONFORMIDADE DOS SERVIÇOS EXECUTADOS COM AS ESPECIFICAÇÕES TÉCNICAS | H12: =IFERROR(VLOOKUP(G12,'Parâmetros'!$A$2:$B$4,2,FALSE),0)
A13: Pontuação total do Módulo A | H13: =SUM(H11:H12)
A14: Módulo B — EQUIPE DE TRABALHO | I14: Peso 25
A15: B.1 | B15: UNIFORMIZAÇÃO E EQUIPAMENTOS DE PROTEÇÃO INDIVIDUAL | H15: =IFERROR(VLOOKUP(G15,'Parâmetros'!$A$2:$B$4,2,FALSE),0)
A16: B.2 | B16: QUALIDADE DA EQUIPE | H16: =IFERROR(VLOOKUP(G16,'Parâmetros'!$A$2:$B$4,2,FALSE),0)
A17: Pontuação total do Módulo B | H17: =SUM(H15:H16)
A18: Módulo C — CUMPRIMENTO DO CRONOGRAMA | I18: Peso 25
A19: C.1 | B19: CUMPRIMENTO DO CRONOGRAMA E DAS ATIVIDADES | H19: =IFERROR(VLOOKUP(G19,'Parâmetros'!$A$2:$B$4,2,FALSE),0)
A20: Pontuação total do Módulo C | H20: =SUM(H19:H19)
A21: TOTAL DE PONTOS | C21: =(H11+H12+H15+H16+H19)/5 | D21: NOTA OBTIDA | F21: =VLOOKUP(C21,'Parâmetros'!$D$2:$F$8,2,TRUE) | G21: % DE LIBERAÇÃO | I21: =VLOOKUP(C21,'Parâmetros'!$D$2:$F$8,3,TRUE)
A23: MÃO DE OBRA COM DEDICAÇÃO EXCLUSIVA
A24: Categoria/Cargo | C24: Postos | D24: Valor Unitário (do posto) | E24: Valor Mensal (postos × unitário) | F24: Horas Contratadas | G24: Qtd. de faltas (em horas) | H24: Valor da Hora | I24: Valor com desconto
A25: ='JUL-27'!A25 | C25: ='JUL-27'!C25 | D25: ='JUL-27'!D25 | E25: =C25*D25 | F25: =C25*'Parâmetros'!$I$2 | H25: =IF(F25=0,0,E25/F25) | I25: =H25*N(G25)
A26: ='JUL-27'!A26 | C26: ='JUL-27'!C26 | D26: ='JUL-27'!D26 | E26: =C26*D26 | F26: =C26*'Parâmetros'!$I$2 | H26: =IF(F26=0,0,E26/F26) | I26: =H26*N(G26)
A27: ='JUL-27'!A27 | C27: ='JUL-27'!C27 | D27: ='JUL-27'!D27 | E27: =C27*D27 | F27: =C27*'Parâmetros'!$I$2 | H27: =IF(F27=0,0,E27/F27) | I27: =H27*N(G27)
A28: ='JUL-27'!A28 | C28: ='JUL-27'!C28 | D28: ='JUL-27'!D28 | E28: =C28*D28 | F28: =C28*'Parâmetros'!$I$2 | H28: =IF(F28=0,0,E28/F28) | I28: =H28*N(G28)
A29: ='JUL-27'!A29 | C29: ='JUL-27'!C29 | D29: ='JUL-27'!D29 | E29: =C29*D29 | F29: =C29*'Parâmetros'!$I$2 | H29: =IF(F29=0,0,E29/F29) | I29: =H29*N(G29)
A30: ='JUL-27'!A30 | C30: ='JUL-27'!C30 | D30: ='JUL-27'!D30 | E30: =C30*D30 | F30: =C30*'Parâmetros'!$I$2 | H30: =IF(F30=0,0,E30/F30) | I30: =H30*N(G30)
A31: TOTAIS | C31: =SUM(C25:C30) | E31: =SUM(E25:E30) | F31: =SUM(F25:F30) | G31: =SUM(G25:G30) | I31: =SUM(I25:I30)
A33: REEMBOLSO DE CRECHE
A34: Qtde contratada | C34: Valor estimado unitário | D34: Valor retido (mensal) | E34: Reembolsos aprovados | F34: Valor por dependente | G34: Total dos reembolsos | H34: Saldo acumulado
A35: =C31 | C35: ='JUL-27'!C35 | D35: =A35*C35 | E35: 0 | F35: ='JUL-27'!F35 | G35: =E35*F35 | H35: ='JUL-27'!H35+D35-G35
A36: Retido = qtde contratada × valor estimado unitário · Total = reembolsos aprovados × valor por dependente · Saldo = saldo do mês anterior + retido − total.
A38: APURAÇÃO DO VALOR A FATURAR
A39: MEDIÇÃO DOS SERVIÇOS | F39: VALOR LIBERADO PARA FATURAMENTO
A40: VALOR UNITÁRIO (planilha orçamentária) | D40: ='JUL-27'!D40 | F40: Valor dos serviços
A41: Dias Trabalhados no mês | D41: 25 | F41: Percentual de liberação (nota obtida) | I41: =I21
A42: Qtde contratada (soma dos postos) | D42: =C31 | F42: Subtotal dos serviços | I42: =I40*I41
A43: Serviço de mão-de-obra (total mensal ÷ 30 × dias) | D43: =E31/'Parâmetros'!$I$3*D41 | F43: Valor do desconto (nota) | I43: =I42-I40
...

Sheet SET-27
A1: UNIVERSIDADE FEDERAL DO RIO DE JANEIRO — PRÓ-REITORIA DE GESTÃO E GOVERNANÇA (PR-6)
A2: INSTRUMENTO DE MEDIÇÃO DE RESULTADO | H2: IMR Nº | I2: ='AGO-27'!I2
A3: OBJETO | B3: ='AGO-27'!B3
A4: EMPRESA | B4: ='AGO-27'!B4 | F4: CONTRATO | G4: ='AGO-27'!G4
A5: UNIDADE | B5: ='AGO-27'!B5 | F5: TERMO | G5: ='AGO-27'!G5
A6: MÊS/ANO | B6: =EDATE('AGO-27'!B6,1) | F6: FISCAL
A7: Preencha as células em amarelo. Pontuação, nota e valores são calculados automaticamente.
A8: AVALIAÇÃO DOS SERVIÇOS
A9: Cód. | B9: Indicador | G9: Avaliação correspondente | H9: Pontos | I9: Peso
A10: Módulo A — QUALIDADE DOS SERVIÇOS | I10: Peso 25
A11: A.1 | B11: CONFORMIDADE DOS EQUIPAMENTOS PARA EXECUÇÃO DOS SERVIÇOS | H11: =IFERROR(VLOOKUP(G11,'Parâmetros'!$A$2:$B$4,2,FALSE),0)
A12: A.2 | B12: CONFORMIDADE DOS SERVIÇOS EXECUTADOS COM AS ESPECIFICAÇÕES TÉCNICAS | H12: =IFERROR(VLOOKUP(G12,'Parâmetros'!$A$2:$B$4,2,FALSE),0)
A13: Pontuação total do Módulo A | H13: =SUM(H11:H12)
A14: Módulo B — EQUIPE DE TRABALHO | I14: Peso 25
A15: B.1 | B15: UNIFORMIZAÇÃO E EQUIPAMENTOS DE PROTEÇÃO INDIVIDUAL | H15: =IFERROR(VLOOKUP(G15,'Parâmetros'!$A$2:$B$4,2,FALSE),0)
A16: B.2 | B16: QUALIDADE DA EQUIPE | H16: =IFERROR(VLOOKUP(G16,'Parâmetros'!$A$2:$B$4,2,FALSE),0)
A17: Pontuação total do Módulo B | H17: =SUM(H15:H16)
A18: Módulo C — CUMPRIMENTO DO CRONOGRAMA | I18: Peso 25
A19: C.1 | B19: CUMPRIMENTO DO CRONOGRAMA E DAS ATIVIDADES | H19: =IFERROR(VLOOKUP(G19,'Parâmetros'!$A$2:$B$4,2,FALSE),0)
A20: Pontuação total do Módulo C | H20: =SUM(H19:H19)
A21: TOTAL DE PONTOS | C21: =(H11+H12+H15+H16+H19)/5 | D21: NOTA OBTIDA | F21: =VLOOKUP(C21,'Parâmetros'!$D$2:$F$8,2,TRUE) | G21: % DE LIBERAÇÃO | I21: =VLOOKUP(C21,'Parâmetros'!$D$2:$F$8,3,TRUE)
A23: MÃO DE OBRA COM DEDICAÇÃO EXCLUSIVA
A24: Categoria/Cargo | C24: Postos | D24: Valor Unitário (do posto) | E24: Valor Mensal (postos × unitário) | F24: Horas Contratadas | G24: Qtd. de faltas (em horas) | H24: Valor da Hora | I24: Valor com desconto
A25: ='AGO-27'!A25 | C25: ='AGO-27'!C25 | D25: ='AGO-27'!D25 | E25: =C25*D25 | F25: =C25*'Parâmetros'!$I$2 | H25: =IF(F25=0,0,E25/F25) | I25: =H25*N(G25)
A26: ='AGO-27'!A26 | C26: ='AGO-27'!C26 | D26: ='AGO-27'!D26 | E26: =C26*D26 | F26: =C26*'Parâmetros'!$I$2 | H26: =IF(F26=0,0,E26/F26) | I26: =H26*N(G26)
A27: ='AGO-27'!A27 | C27: ='AGO-27'!C27 | D27: ='AGO-27'!D27 | E27: =C27*D27 | F27: =C27*'Parâmetros'!$I$2 | H27: =IF(F27=0,0,E27/F27) | I27: =H27*N(G27)
A28: ='AGO-27'!A28 | C28: ='AGO-27'!C28 | D28: ='AGO-27'!D28 | E28: =C28*D28 | F28: =C28*'Parâmetros'!$I$2 | H28: =IF(F28=0,0,E28/F28) | I28: =H28*N(G28)
A29: ='AGO-27'!A29 | C29: ='AGO-27'!C29 | D29: ='AGO-27'!D29 | E29: =C29*D29 | F29: =C29*'Parâmetros'!$I$2 | H29: =IF(F29=0,0,E29/F29) | I29: =H29*N(G29)
A30: ='AGO-27'!A30 | C30: ='AGO-27'!C30 | D30: ='AGO-27'!D30 | E30: =C30*D30 | F30: =C30*'Parâmetros'!$I$2 | H30: =IF(F30=0,0,E30/F30) | I30: =H30*N(G30)
A31: TOTAIS | C31: =SUM(C25:C30) | E31: =SUM(E25:E30) | F31: =SUM(F25:F30) | G31: =SUM(G25:G30) | I31: =SUM(I25:I30)
A33: REEMBOLSO DE CRECHE
A34: Qtde contratada | C34: Valor estimado unitário | D34: Valor retido (mensal) | E34: Reembolsos aprovados | F34: Valor por dependente | G34: Total dos reembolsos | H34: Saldo acumulado
A35: =C31 | C35: ='AGO-27'!C35 | D35: =A35*C35 | E35: 0 | F35: ='AGO-27'!F35 | G35: =E35*F35 | H35: ='AGO-27'!H35+D35-G35
A36: Retido = qtde contratada × valor estimado unitário · Total = reembolsos aprovados × valor por dependente · Saldo = saldo do mês anterior + retido − total.
A38: APURAÇÃO DO VALOR A FATURAR
A39: MEDIÇÃO DOS SERVIÇOS | F39: VALOR LIBERADO PARA FATURAMENTO
A40: VALOR UNITÁRIO (planilha orçamentária) | D40: ='AGO-27'!D40 | F40: Valor dos serviços
A41: Dias Trabalhados no mês | D41: 25 | F41: Percentual de liberação (nota obtida) | I41: =I21
A42: Qtde contratada (soma dos postos) | D42: =C31 | F42: Subtotal dos serviços | I42: =I40*I41
A43: Serviço de mão-de-obra (total mensal ÷ 30 × dias) | D43: =E31/'Parâmetros'!$I$3*D41 | F43: Valor do desconto (nota) | I43: =I42-I40
...

Sheet OUT-27
A1: UNIVERSIDADE FEDERAL DO RIO DE JANEIRO — PRÓ-REITORIA DE GESTÃO E GOVERNANÇA (PR-6)
A2: INSTRUMENTO DE MEDIÇÃO DE RESULTADO | H2: IMR Nº | I2: ='SET-27'!I2
A3: OBJETO | B3: ='SET-27'!B3
A4: EMPRESA | B4: ='SET-27'!B4 | F4: CONTRATO | G4: ='SET-27'!G4
A5: UNIDADE | B5: ='SET-27'!B5 | F5: TERMO | G5: ='SET-27'!G5
A6: MÊS/ANO | B6: =EDATE('SET-27'!B6,1) | F6: FISCAL
A7: Preencha as células em amarelo. Pontuação, nota e valores são calculados automaticamente.
A8: AVALIAÇÃO DOS SERVIÇOS
A9: Cód. | B9: Indicador | G9: Avaliação correspondente | H9: Pontos | I9: Peso
A10: Módulo A — QUALIDADE DOS SERVIÇOS | I10: Peso 25
A11: A.1 | B11: CONFORMIDADE DOS EQUIPAMENTOS PARA EXECUÇÃO DOS SERVIÇOS | H11: =IFERROR(VLOOKUP(G11,'Parâmetros'!$A$2:$B$4,2,FALSE),0)
A12: A.2 | B12: CONFORMIDADE DOS SERVIÇOS EXECUTADOS COM AS ESPECIFICAÇÕES TÉCNICAS | H12: =IFERROR(VLOOKUP(G12,'Parâmetros'!$A$2:$B$4,2,FALSE),0)
A13: Pontuação total do Módulo A | H13: =SUM(H11:H12)
A14: Módulo B — EQUIPE DE TRABALHO | I14: Peso 25
A15: B.1 | B15: UNIFORMIZAÇÃO E EQUIPAMENTOS DE PROTEÇÃO INDIVIDUAL | H15: =IFERROR(VLOOKUP(G15,'Parâmetros'!$A$2:$B$4,2,FALSE),0)
A16: B.2 | B16: QUALIDADE DA EQUIPE | H16: =IFERROR(VLOOKUP(G16,'Parâmetros'!$A$2:$B$4,2,FALSE),0)
A17: Pontuação total do Módulo B | H17: =SUM(H15:H16)
A18: Módulo C — CUMPRIMENTO DO CRONOGRAMA | I18: Peso 25
A19: C.1 | B19: CUMPRIMENTO DO CRONOGRAMA E DAS ATIVIDADES | H19: =IFERROR(VLOOKUP(G19,'Parâmetros'!$A$2:$B$4,2,FALSE),0)
A20: Pontuação total do Módulo C | H20: =SUM(H19:H19)
A21: TOTAL DE PONTOS | C21: =(H11+H12+H15+H16+H19)/5 | D21: NOTA OBTIDA | F21: =VLOOKUP(C21,'Parâmetros'!$D$2:$F$8,2,TRUE) | G21: % DE LIBERAÇÃO | I21: =VLOOKUP(C21,'Parâmetros'!$D$2:$F$8,3,TRUE)
A23: MÃO DE OBRA COM DEDICAÇÃO EXCLUSIVA
A24: Categoria/Cargo | C24: Postos | D24: Valor Unitário (do posto) | E24: Valor Mensal (postos × unitário) | F24: Horas Contratadas | G24: Qtd. de faltas (em horas) | H24: Valor da Hora | I24: Valor com desconto
A25: ='SET-27'!A25 | C25: ='SET-27'!C25 | D25: ='SET-27'!D25 | E25: =C25*D25 | F25: =C25*'Parâmetros'!$I$2 | H25: =IF(F25=0,0,E25/F25) | I25: =H25*N(G25)
A26: ='SET-27'!A26 | C26: ='SET-27'!C26 | D26: ='SET-27'!D26 | E26: =C26*D26 | F26: =C26*'Parâmetros'!$I$2 | H26: =IF(F26=0,0,E26/F26) | I26: =H26*N(G26)
A27: ='SET-27'!A27 | C27: ='SET-27'!C27 | D27: ='SET-27'!D27 | E27: =C27*D27 | F27: =C27*'Parâmetros'!$I$2 | H27: =IF(F27=0,0,E27/F27) | I27: =H27*N(G27)
A28: ='SET-27'!A28 | C28: ='SET-27'!C28 | D28: ='SET-27'!D28 | E28: =C28*D28 | F28: =C28*'Parâmetros'!$I$2 | H28: =IF(F28=0,0,E28/F28) | I28: =H28*N(G28)
A29: ='SET-27'!A29 | C29: ='SET-27'!C29 | D29: ='SET-27'!D29 | E29: =C29*D29 | F29: =C29*'Parâmetros'!$I$2 | H29: =IF(F29=0,0,E29/F29) | I29: =H29*N(G29)
A30: ='SET-27'!A30 | C30: ='SET-27'!C30 | D30: ='SET-27'!D30 | E30: =C30*D30 | F30: =C30*'Parâmetros'!$I$2 | H30: =IF(F30=0,0,E30/F30) | I30: =H30*N(G30)
A31: TOTAIS | C31: =SUM(C25:C30) | E31: =SUM(E25:E30) | F31: =SUM(F25:F30) | G31: =SUM(G25:G30) | I31: =SUM(I25:I30)
A33: REEMBOLSO DE CRECHE
A34: Qtde contratada | C34: Valor estimado unitário | D34: Valor retido (mensal) | E34: Reembolsos aprovados | F34: Valor por dependente | G34: Total dos reembolsos | H34: Saldo acumulado
A35: =C31 | C35: ='SET-27'!C35 | D35: =A35*C35 | E35: 0 | F35: ='SET-27'!F35 | G35: =E35*F35 | H35: ='SET-27'!H35+D35-G35
A36: Retido = qtde contratada × valor estimado unitário · Total = reembolsos aprovados × valor por dependente · Saldo = saldo do mês anterior + retido − total.
A38: APURAÇÃO DO VALOR A FATURAR
A39: MEDIÇÃO DOS SERVIÇOS | F39: VALOR LIBERADO PARA FATURAMENTO
A40: VALOR UNITÁRIO (planilha orçamentária) | D40: ='SET-27'!D40 | F40: Valor dos serviços
A41: Dias Trabalhados no mês | D41: 25 | F41: Percentual de liberação (nota obtida) | I41: =I21
A42: Qtde contratada (soma dos postos) | D42: =C31 | F42: Subtotal dos serviços | I42: =I40*I41
A43: Serviço de mão-de-obra (total mensal ÷ 30 × dias) | D43: =E31/'Parâmetros'!$I$3*D41 | F43: Valor do desconto (nota) | I43: =I42-I40
...

Sheet NOV-27
A1: UNIVERSIDADE FEDERAL DO RIO DE JANEIRO — PRÓ-REITORIA DE GESTÃO E GOVERNANÇA (PR-6)
A2: INSTRUMENTO DE MEDIÇÃO DE RESULTADO | H2: IMR Nº | I2: ='OUT-27'!I2
A3: OBJETO | B3: ='OUT-27'!B3
A4: EMPRESA | B4: ='OUT-27'!B4 | F4: CONTRATO | G4: ='OUT-27'!G4
A5: UNIDADE | B5: ='OUT-27'!B5 | F5: TERMO | G5: ='OUT-27'!G5
A6: MÊS/ANO | B6: =EDATE('OUT-27'!B6,1) | F6: FISCAL
A7: Preencha as células em amarelo. Pontuação, nota e valores são calculados automaticamente.
A8: AVALIAÇÃO DOS SERVIÇOS
A9: Cód. | B9: Indicador | G9: Avaliação correspondente | H9: Pontos | I9: Peso
A10: Módulo A — QUALIDADE DOS SERVIÇOS | I10: Peso 25
A11: A.1 | B11: CONFORMIDADE DOS EQUIPAMENTOS PARA EXECUÇÃO DOS SERVIÇOS | H11: =IFERROR(VLOOKUP(G11,'Parâmetros'!$A$2:$B$4,2,FALSE),0)
A12: A.2 | B12: CONFORMIDADE DOS SERVIÇOS EXECUTADOS COM AS ESPECIFICAÇÕES TÉCNICAS | H12: =IFERROR(VLOOKUP(G12,'Parâmetros'!$A$2:$B$4,2,FALSE),0)
A13: Pontuação total do Módulo A | H13: =SUM(H11:H12)
A14: Módulo B — EQUIPE DE TRABALHO | I14: Peso 25
A15: B.1 | B15: UNIFORMIZAÇÃO E EQUIPAMENTOS DE PROTEÇÃO INDIVIDUAL | H15: =IFERROR(VLOOKUP(G15,'Parâmetros'!$A$2:$B$4,2,FALSE),0)
A16: B.2 | B16: QUALIDADE DA EQUIPE | H16: =IFERROR(VLOOKUP(G16,'Parâmetros'!$A$2:$B$4,2,FALSE),0)
A17: Pontuação total do Módulo B | H17: =SUM(H15:H16)
A18: Módulo C — CUMPRIMENTO DO CRONOGRAMA | I18: Peso 25
A19: C.1 | B19: CUMPRIMENTO DO CRONOGRAMA E DAS ATIVIDADES | H19: =IFERROR(VLOOKUP(G19,'Parâmetros'!$A$2:$B$4,2,FALSE),0)
A20: Pontuação total do Módulo C | H20: =SUM(H19:H19)
A21: TOTAL DE PONTOS | C21: =(H11+H12+H15+H16+H19)/5 | D21: NOTA OBTIDA | F21: =VLOOKUP(C21,'Parâmetros'!$D$2:$F$8,2,TRUE) | G21: % DE LIBERAÇÃO | I21: =VLOOKUP(C21,'Parâmetros'!$D$2:$F$8,3,TRUE)
A23: MÃO DE OBRA COM DEDICAÇÃO EXCLUSIVA
A24: Categoria/Cargo | C24: Postos | D24: Valor Unitário (do posto) | E24: Valor Mensal (postos × unitário) | F24: Horas Contratadas | G24: Qtd. de faltas (em horas) | H24: Valor da Hora | I24: Valor com desconto
A25: ='OUT-27'!A25 | C25: ='OUT-27'!C25 | D25: ='OUT-27'!D25 | E25: =C25*D25 | F25: =C25*'Parâmetros'!$I$2 | H25: =IF(F25=0,0,E25/F25) | I25: =H25*N(G25)
A26: ='OUT-27'!A26 | C26: ='OUT-27'!C26 | D26: ='OUT-27'!D26 | E26: =C26*D26 | F26: =C26*'Parâmetros'!$I$2 | H26: =IF(F26=0,0,E26/F26) | I26: =H26*N(G26)
A27: ='OUT-27'!A27 | C27: ='OUT-27'!C27 | D27: ='OUT-27'!D27 | E27: =C27*D27 | F27: =C27*'Parâmetros'!$I$2 | H27: =IF(F27=0,0,E27/F27) | I27: =H27*N(G27)
A28: ='OUT-27'!A28 | C28: ='OUT-27'!C28 | D28: ='OUT-27'!D28 | E28: =C28*D28 | F28: =C28*'Parâmetros'!$I$2 | H28: =IF(F28=0,0,E28/F28) | I28: =H28*N(G28)
A29: ='OUT-27'!A29 | C29: ='OUT-27'!C29 | D29: ='OUT-27'!D29 | E29: =C29*D29 | F29: =C29*'Parâmetros'!$I$2 | H29: =IF(F29=0,0,E29/F29) | I29: =H29*N(G29)
A30: ='OUT-27'!A30 | C30: ='OUT-27'!C30 | D30: ='OUT-27'!D30 | E30: =C30*D30 | F30: =C30*'Parâmetros'!$I$2 | H30: =IF(F30=0,0,E30/F30) | I30: =H30*N(G30)
A31: TOTAIS | C31: =SUM(C25:C30) | E31: =SUM(E25:E30) | F31: =SUM(F25:F30) | G31: =SUM(G25:G30) | I31: =SUM(I25:I30)
A33: REEMBOLSO DE CRECHE
A34: Qtde contratada | C34: Valor estimado unitário | D34: Valor retido (mensal) | E34: Reembolsos aprovados | F34: Valor por dependente | G34: Total dos reembolsos | H34: Saldo acumulado
A35: =C31 | C35: ='OUT-27'!C35 | D35: =A35*C35 | E35: 0 | F35: ='OUT-27'!F35 | G35: =E35*F35 | H35: ='OUT-27'!H35+D35-G35
A36: Retido = qtde contratada × valor estimado unitário · Total = reembolsos aprovados × valor por dependente · Saldo = saldo do mês anterior + retido − total.
A38: APURAÇÃO DO VALOR A FATURAR
A39: MEDIÇÃO DOS SERVIÇOS | F39: VALOR LIBERADO PARA FATURAMENTO
A40: VALOR UNITÁRIO (planilha orçamentária) | D40: ='OUT-27'!D40 | F40: Valor dos serviços
A41: Dias Trabalhados no mês | D41: 25 | F41: Percentual de liberação (nota obtida) | I41: =I21
A42: Qtde contratada (soma dos postos) | D42: =C31 | F42: Subtotal dos serviços | I42: =I40*I41
A43: Serviço de mão-de-obra (total mensal ÷ 30 × dias) | D43: =E31/'Parâmetros'!$I$3*D41 | F43: Valor do desconto (nota) | I43: =I42-I40
...

Sheet DEZ-27
A1: UNIVERSIDADE FEDERAL DO RIO DE JANEIRO — PRÓ-REITORIA DE GESTÃO E GOVERNANÇA (PR-6)
A2: INSTRUMENTO DE MEDIÇÃO DE RESULTADO | H2: IMR Nº | I2: ='NOV-27'!I2
A3: OBJETO | B3: ='NOV-27'!B3
A4: EMPRESA | B4: ='NOV-27'!B4 | F4: CONTRATO | G4: ='NOV-27'!G4
A5: UNIDADE | B5: ='NOV-27'!B5 | F5: TERMO | G5: ='NOV-27'!G5
A6: MÊS/ANO | B6: =EDATE('NOV-27'!B6,1) | F6: FISCAL
A7: Preencha as células em amarelo. Pontuação, nota e valores são calculados automaticamente.
A8: AVALIAÇÃO DOS SERVIÇOS
A9: Cód. | B9: Indicador | G9: Avaliação correspondente | H9: Pontos | I9: Peso
A10: Módulo A — QUALIDADE DOS SERVIÇOS | I10: Peso 25
A11: A.1 | B11: CONFORMIDADE DOS EQUIPAMENTOS PARA EXECUÇÃO DOS SERVIÇOS | H11: =IFERROR(VLOOKUP(G11,'Parâmetros'!$A$2:$B$4,2,FALSE),0)
A12: A.2 | B12: CONFORMIDADE DOS SERVIÇOS EXECUTADOS COM AS ESPECIFICAÇÕES TÉCNICAS | H12: =IFERROR(VLOOKUP(G12,'Parâmetros'!$A$2:$B$4,2,FALSE),0)
A13: Pontuação total do Módulo A | H13: =SUM(H11:H12)
A14: Módulo B — EQUIPE DE TRABALHO | I14: Peso 25
A15: B.1 | B15: UNIFORMIZAÇÃO E EQUIPAMENTOS DE PROTEÇÃO INDIVIDUAL | H15: =IFERROR(VLOOKUP(G15,'Parâmetros'!$A$2:$B$4,2,FALSE),0)
A16: B.2 | B16: QUALIDADE DA EQUIPE | H16: =IFERROR(VLOOKUP(G16,'Parâmetros'!$A$2:$B$4,2,FALSE),0)
A17: Pontuação total do Módulo B | H17: =SUM(H15:H16)
A18: Módulo C — CUMPRIMENTO DO CRONOGRAMA | I18: Peso 25
A19: C.1 | B19: CUMPRIMENTO DO CRONOGRAMA E DAS ATIVIDADES | H19: =IFERROR(VLOOKUP(G19,'Parâmetros'!$A$2:$B$4,2,FALSE),0)
A20: Pontuação total do Módulo C | H20: =SUM(H19:H19)
A21: TOTAL DE PONTOS | C21: =(H11+H12+H15+H16+H19)/5 | D21: NOTA OBTIDA | F21: =VLOOKUP(C21,'Parâmetros'!$D$2:$F$8,2,TRUE) | G21: % DE LIBERAÇÃO | I21: =VLOOKUP(C21,'Parâmetros'!$D$2:$F$8,3,TRUE)
A23: MÃO DE OBRA COM DEDICAÇÃO EXCLUSIVA
A24: Categoria/Cargo | C24: Postos | D24: Valor Unitário (do posto) | E24: Valor Mensal (postos × unitário) | F24: Horas Contratadas | G24: Qtd. de faltas (em horas) | H24: Valor da Hora | I24: Valor com desconto
A25: ='NOV-27'!A25 | C25: ='NOV-27'!C25 | D25: ='NOV-27'!D25 | E25: =C25*D25 | F25: =C25*'Parâmetros'!$I$2 | H25: =IF(F25=0,0,E25/F25) | I25: =H25*N(G25)
A26: ='NOV-27'!A26 | C26: ='NOV-27'!C26 | D26: ='NOV-27'!D26 | E26: =C26*D26 | F26: =C26*'Parâmetros'!$I$2 | H26: =IF(F26=0,0,E26/F26) | I26: =H26*N(G26)
A27: ='NOV-27'!A27 | C27: ='NOV-27'!C27 | D27: ='NOV-27'!D27 | E27: =C27*D27 | F27: =C27*'Parâmetros'!$I$2 | H27: =IF(F27=0,0,E27/F27) | I27: =H27*N(G27)
A28: ='NOV-27'!A28 | C28: ='NOV-27'!C28 | D28: ='NOV-27'!D28 | E28: =C28*D28 | F28: =C28*'Parâmetros'!$I$2 | H28: =IF(F28=0,0,E28/F28) | I28: =H28*N(G28)
A29: ='NOV-27'!A29 | C29: ='NOV-27'!C29 | D29: ='NOV-27'!D29 | E29: =C29*D29 | F29: =C29*'Parâmetros'!$I$2 | H29: =IF(F29=0,0,E29/F29) | I29: =H29*N(G29)
A30: ='NOV-27'!A30 | C30: ='NOV-27'!C30 | D30: ='NOV-27'!D30 | E30: =C30*D30 | F30: =C30*'Parâmetros'!$I$2 | H30: =IF(F30=0,0,E30/F30) | I30: =H30*N(G30)
A31: TOTAIS | C31: =SUM(C25:C30) | E31: =SUM(E25:E30) | F31: =SUM(F25:F30) | G31: =SUM(G25:G30) | I31: =SUM(I25:I30)
A33: REEMBOLSO DE CRECHE
A34: Qtde contratada | C34: Valor estimado unitário | D34: Valor retido (mensal) | E34: Reembolsos aprovados | F34: Valor por dependente | G34: Total dos reembolsos | H34: Saldo acumulado
